Workbook

Sheet Carro Emergencia I
A1: UNIDADE DE TERAPIA INTENSIVA | M1: Alerta
G2: Data: | H2: =TODAY() -> 46073 | M2: Atenção
A3: LISTA DE CONFERENCIA DO CARRO DE EMERGÊNCIA 1
A4: 1ª GAVETA | G4: Lacre:
A5: Qtade | B5: Farmaco | C5: Nome Comercial | D5: Apresentação | F5: Total | G5: Validade | H5: Lote | I5: Dias
A6: 3 | B6: AAS | C6: Acetilsalicilico | D6: 100 mg | E6: cp | F6: =COUNTA(G6:G8) -> 0 | I6: =IF(G6="","",G6-H$2)
I7: =IF(G7="","",G7-H$2)
I8: =IF(G8="","",G8-H$2)
A9: 6 | B9: Clopidrogrel | C9: Plavix | D9: 75 mg | E9: cp | F9: =COUNTA(G9:G14) -> 0 | I9: =IF(G9="","",G9-H$2)
I10: =IF(G10="","",G10-H$2)
I11: =IF(G11="","",G11-H$2)
I12: =IF(G12="","",G12-H$2)
I13: =IF(G13="","",G13-H$2)
I14: =IF(G14="","",G14-H$2)
A15: 2 | B15: Isossorbida | C15: Isordil | D15: 5 mg | E15: cp | F15: =COUNTA(G15:G16) -> 0 | I15: =IF(G15="","",G15-H$2)
I16: =IF(G16="","",G16-H$2)
A17: 20 | B17: Adrenalina | C17: Adren | D17: 1mg / ml | E17: ap | F17: =COUNTA(G17:G36) -> 0 | I17: =IF(G17="","",G17-H$2)
I18: =IF(G18="","",G18-H$2)
I19: =IF(G19="","",G19-H$2)
I20: =IF(G20="","",G20-H$2)
I21: =IF(G21="","",G21-H$2)
I22: =IF(G22="","",G22-H$2)
I23: =IF(G23="","",G23-H$2)
I24: =IF(G24="","",G24-H$2)
I25: =IF(G25="","",G25-H$2)
I26: =IF(G26="","",G26-H$2)
I27: =IF(G27="","",G27-H$2)
I28: =IF(G28="","",G28-H$2)
I29: =IF(G29="","",G29-H$2)
... I36: =IF(G36="","",G36-H$2)
A37: 5 | B37: Adenosina | D37: 3mg/ ml | E37: ap | F37: =COUNTA(G37:G41) -> 0 | I37: =IF(G37="","",G37-H$2)
I38: =IF(G38="","",G38-H$2)
I39: =IF(G39="","",G39-H$2)
I40: =IF(G40="","",G40-H$2)
I41: =IF(G41="","",G41-H$2)
A42: 5 | B42: Agua Destilada | D42: 10 ml | E42: ap | F42: =COUNTA(G42:G46) -> 0 | I42: =IF(G42="","",G42-H$2)
I43: =IF(G43="","",G43-H$2)
I44: =IF(G44="","",G44-H$2)
I45: =IF(G45="","",G45-H$2)
I46: =IF(G46="","",G46-H$2)
...

Sheet Planilha1
B3: Coberturas / Cooperativa Estratégia
B4: Diurno | C4: Setores | D4: 44884 | E4: 44885 | F4: 44886 | G4: 44887
C5: PA | D5: 1 | E5: 1
C6: UTI
C7: 3º andar | E7: 2 | G7: 1
B8: Enfermeiro(a) | D8: Jaqueline | E8: Bruna R | G8: Bruna R
B10: Noturno | C10: Setores | D10: 44884 | E10: 44885 | F10: 44886 | G10: 44887
C11: PA
C12: UTI | D12: 1 | F12: 1
C13: 3º andar | D13: 1 | F13: 1
B14: Enfermeiro(a) | D14: Amanda | F14: Amanda

Sheet Planilha2
B3: Colaboradores Afastados
B4: Diurno | C4: Setores | D4: 44883 | E4: 44884 | F4: 44885 | G4: 44886 | H4: 44887 | I4: 44888 | J4: 44889 | K4: 44890 | L4: 44891 | M4: 44892 | N4: 44893 | O4: 44894 | P4: 44895
C5: PA | D5: 3 | E5: 1 | F5: 3
C6: Ambulatorio
C7: Centro C
C8: UTI | D8: 1 | F8: 1
C9: Enfermaria | D9: 2 | F9: 2 | H9: 2
B11: Noturno | C11: PA
C12: Ambulatorio
C13: Centro C
C14: UTI
C15: Enfermaria

Sheet Intercorrencias
B5: Data | C5: Setor | D5: Colaborador | E5: Observação

Sheet Enfermeiros
A5: ENFERMEIROS
A7: AGOSTO DE 2022 | E7: 1 | F7: 2 | G7: 3 | H7: 4 | I7: 5 | J7: 6 | K7: 7 | L7: 8 | M7: 9 | N7: 10 | O7: 11 | P7: 12 | Q7: 13 | R7: 14 | S7: 15 | T7: 16 | U7: 17 | V7: 18 | W7: 19 | X7: 20 | Y7: 21 | Z7: 22 | AA7: 23 | AB7: 24 | AC7: 25 | AD7: 26 | AE7: 27 | AF7: 28 | AG7: 29 | AH7: 30 | AI7: 31
A8: PRONTO ATENDIMENTO | E8: S | F8: T | G8: Q | H8: Q | I8: S | J8: S | K8: D | L8: S | M8: T | N8: Q | O8: Q | P8: S | Q8: S | R8: D | S8: S | T8: T | U8: Q | V8: Q | W8: S | X8: S | Y8: D | Z8: S | AA8: T | AB8: Q | AC8: Q | AD8: S | AE8: S | AF8: D | AG8: S | AH8: T | AI8: Q
A9: =#REF! -> #REF! | B9: =#REF! -> #REF! | C9: =#REF! -> #REF! | D9: =#REF! -> #REF! | E9: =#REF! -> #REF! | F9: =#REF! -> #REF! | G9: =#REF! -> #REF! | H9: =#REF! -> #REF! | ... AI9: =#REF! -> #REF!
A10: =#REF! -> #REF! | B10: =#REF! -> #REF! | C10: =#REF! -> #REF! | D10: =#REF! -> #REF! | E10: =#REF! -> #REF! | F10: =#REF! -> #REF! | G10: =#REF! -> #REF! | H10: =#REF! -> #REF! | ... AH10: =#REF! -> #REF!
A11: =#REF! -> #REF! | B11: =#REF! -> #REF! | C11: =#REF! -> #REF! | D11: =#REF! -> #REF! | E11: =#REF! -> #REF! | F11: =#REF! -> #REF! | G11: =#REF! -> #REF! | H11: =#REF! -> #REF! | ... AI11: =#REF! -> #REF!
A12: =#REF! -> #REF! | B12: =#REF! -> #REF! | C12: =#REF! -> #REF! | D12: =#REF! -> #REF! | E12: =#REF! -> #REF! | F12: =#REF! -> #REF! | G12: =#REF! -> #REF! | H12: =#REF! -> #REF! | ... AI12: =#REF! -> #REF!
A13: =#REF! -> #REF! | B13: =#REF! -> #REF! | C13: =#REF! -> #REF! | D13: =#REF! -> #REF! | E13: =#REF! -> #REF! | F13: =#REF! -> #REF! | G13: =#REF! -> #REF! | H13: =#REF! -> #REF! | ... AI13: =#REF! -> #REF!
A15: AMBULATÓRIO
A16: =#REF! -> #REF! | B16: =#REF! -> #REF! | C16: =#REF! -> #REF! | D16: =#REF! -> #REF! | E16: =#REF! -> #REF! | F16: =#REF! -> #REF! | G16: =#REF! -> #REF! | H16: =#REF! -> #REF! | ... AI16: =#REF! -> #REF!
A18: ENFERMARIA
A19: =#REF! -> #REF! | B19: =#REF! -> #REF! | C19: =#REF! -> #REF! | D19: =#REF! -> #REF! | E19: =#REF! -> #REF! | F19: =#REF! -> #REF! | G19: =#REF! -> #REF! | H19: =#REF! -> #REF! | ... AI19: =#REF! -> #REF!
A20: =#REF! -> #REF! | B20: =#REF! -> #REF! | C20: =#REF! -> #REF! | D20: =#REF! -> #REF! | E20: =#REF! -> #REF! | F20: =#REF! -> #REF! | G20: =#REF! -> #REF! | H20: =#REF! -> #REF! | ... AI20: =#REF! -> #REF!
A21: =#REF! -> #REF! | B21: =#REF! -> #REF! | C21: =#REF! -> #REF! | D21: =#REF! -> #REF! | E21: =#REF! -> #REF! | F21: =#REF! -> #REF! | G21: =#REF! -> #REF! | H21: =#REF! -> #REF! | ... AI21: =#REF! -> #REF!
A22: =#REF! -> #REF! | B22: =#REF! -> #REF! | C22: =#REF! -> #REF! | D22: =#REF! -> #REF! | E22: =#REF! -> #REF! | O22: =#REF! -> #REF! | P22: =#REF! -> #REF! | Q22: =#REF! -> #REF! | R22: =#REF! -> #REF! | S22: =#REF! -> #REF! | T22: =#REF! -> #REF! | U22: =#REF! -> #REF! | V22: =#REF! -> #REF! | ... AI22: =#REF! -> #REF!
A23: =#REF! -> #REF! | B23: =#REF! -> #REF! | C23: =#REF! -> #REF! | D23: =#REF! -> #REF! | E23: =#REF! -> #REF! | F23: =#REF! -> #REF! | G23: =#REF! -> #REF! | H23: =#REF! -> #REF! | ... M23: =#REF! -> #REF!
A25: CENTRO CIRURGICO
A26: =#REF! -> #REF! | B26: =#REF! -> #REF! | C26: =#REF! -> #REF! | D26: =#REF! -> #REF! | E26: =#REF! -> #REF! | F26: =#REF! -> #REF! | G26: =#REF! -> #REF! | H26: =#REF! -> #REF! | ... AI26: =#REF! -> #REF!
A27: =#REF! -> #REF! | B27: =#REF! -> #REF! | C27: =#REF! -> #REF! | D27: =#REF! -> #REF! | E27: =#REF! -> #REF! | F27: =#REF! -> #REF! | G27: =#REF! -> #REF! | H27: =#REF! -> #REF! | ... AI27: =#REF! -> #REF!
A29: UTI
A30: =#REF! -> #REF! | B30: =#REF! -> #REF! | C30: =#REF! -> #REF! | D30: =#REF! -> #REF! | E30: =#REF! -> #REF! | F30: =#REF! -> #REF! | G30: =#REF! -> #REF! | H30: =#REF! -> #REF! | ... AI30: =#REF! -> #REF!
A31: =#REF! -> #REF! | B31: =#REF! -> #REF! | C31: =#REF! -> #REF! | D31: =#REF! -> #REF! | E31: =#REF! -> #REF! | F31: =#REF! -> #REF! | G31: =#REF! -> #REF! | H31: =#REF! -> #REF! | ... AI31: =#REF! -> #REF!
A32: =#REF! -> #REF! | B32: =#REF! -> #REF! | C32: =#REF! -> #REF! | D32: =#REF! -> #REF! | E32: =#REF! -> #REF! | F32: =#REF! -> #REF! | G32: =#REF! -> #REF! | H32: =#REF! -> #REF! | ... AI32: =#REF! -> #REF!
A33: =#REF! -> #REF! | B33: =#REF! -> #REF! | C33: =#REF! -> #REF! | D33: =#REF! -> #REF! | E33: =#REF! -> #REF! | F33: =#REF! -> #REF! | G33: =#REF! -> #REF! | H33: =#REF! -> #REF! | ... AI33: =#REF! -> #REF!
A34: =#REF! -> #REF! | B34: =#REF! -> #REF! | C34: =#REF! -> #REF! | D34: =#REF! -> #REF! | E34: =#REF! -> #REF! | F34: =#REF! -> #REF! | G34: =#REF! -> #REF! | H34: =#REF! -> #REF! | ... AH34: =#REF! -> #REF! | AI34: SN

Sheet Enfermeiros (2)
A5: ENFERMEIROS
A7: AGOSTO DE 2022 | E7: 1 | F7: 2 | G7: 3 | H7: 4 | I7: 5 | J7: 6 | K7: 7 | L7: 8 | M7: 9 | N7: 10 | O7: 11 | P7: 12 | Q7: 13 | R7: 14 | S7: 15 | T7: 16 | U7: 17 | V7: 18 | W7: 19 | X7: 20 | Y7: 21 | Z7: 22 | AA7: 23 | AB7: 24 | AC7: 25 | AD7: 26 | AE7: 27 | AF7: 28 | AG7: 29 | AH7: 30 | AI7: 31
A8: COLABORADOR | B8: CARGO | C8: COREN | D8: J.TRAB. | E8: S | F8: T | G8: Q | H8: Q | I8: S | J8: S | K8: D | L8: S | M8: T | N8: Q | O8: Q | P8: S | Q8: S | R8: D | S8: S | T8: T | U8: Q | V8: Q | W8: S | X8: S | Y8: D | Z8: S | AA8: T | AB8: Q | AC8: Q | AD8: S | AE8: S | AF8: D | AG8: S | AH8: T | AI8: Q
A9: Reginaldo Costa | B9: G. Enf | C9: 78424 | D9: 8h | E9: P | F9: P | G9: P | H9: P | I9: P | J9: F | K9: F | L9: P | M9: P | N9: P | O9: P | P9: P | Q9: F | R9: F | S9: P | T9: P | U9: P | V9: P | W9: P | X9: F | Y9: F | Z9: P | AA9: P | AB9: P | AC9: P | AD9: P | AE9: F | AF9: F | AG9: P | AH9: P | AI9: P
A10: =Enfermeiros!A9 -> #REF! | B10: =Enfermeiros!B9 -> #REF! | C10: =Enfermeiros!C9 -> #REF! | D10: =Enfermeiros!D9 -> #REF! | E10: =Enfermeiros!E9 -> #REF! | F10: =Enfermeiros!F9 -> #REF! | G10: =Enfermeiros!G9 -> #REF! | H10: =Enfermeiros!H9 -> #REF! | ... AI10: =Enfermeiros!AI9 -> #REF!
A11: =Enfermeiros!A10 -> #REF! | B11: =Enfermeiros!B10 -> #REF! | C11: =Enfermeiros!C10 -> #REF! | D11: =Enfermeiros!D10 -> #REF! | E11: =Enfermeiros!E10 -> #REF! | F11: =Enfermeiros!F10 -> #REF! | G11: =Enfermeiros!G10 -> #REF! | H11: =Enfermeiros!H10 -> #REF! | ... AH11: =Enfermeiros!AH10 -> #REF!
A12: =Enfermeiros!A11 -> #REF! | B12: =Enfermeiros!B11 -> #REF! | C12: =Enfermeiros!C11 -> #REF! | D12: =Enfermeiros!D11 -> #REF! | E12: =Enfermeiros!E11 -> #REF! | F12: =Enfermeiros!F11 -> #REF! | G12: =Enfermeiros!G11 -> #REF! | H12: =Enfermeiros!H11 -> #REF! | ... AI12: =Enfermeiros!AI11 -> #REF!
A13: AMBULATÓRIO
A14: =Enfermeiros!A16 -> #REF! | B14: =Enfermeiros!B16 -> #REF! | C14: =Enfermeiros!C16 -> #REF! | D14: =Enfermeiros!D16 -> #REF! | E14: =Enfermeiros!E16 -> #REF! | F14: =Enfermeiros!F16 -> #REF! | G14: =Enfermeiros!G16 -> #REF! | H14: =Enfermeiros!H16 -> #REF! | ... AI14: =Enfermeiros!AI16 -> #REF!
A15: ENFERMARIA
A16: =Enfermeiros!A19 -> #REF! | B16: =Enfermeiros!B19 -> #REF! | C16: =Enfermeiros!C19 -> #REF! | D16: =Enfermeiros!D19 -> #REF! | E16: =Enfermeiros!E19 -> #REF! | F16: =Enfermeiros!F19 -> #REF! | G16: =Enfermeiros!G19 -> #REF! | H16: =Enfermeiros!H19 -> #REF! | ... AI16: =Enfermeiros!AI19 -> #REF!
A17: =Enfermeiros!A20 -> #REF! | B17: =Enfermeiros!B20 -> #REF! | C17: =Enfermeiros!C20 -> #REF! | D17: =Enfermeiros!D20 -> #REF! | E17: =Enfermeiros!E20 -> #REF! | F17: =Enfermeiros!F20 -> #REF! | G17: =Enfermeiros!G20 -> #REF! | H17: =Enfermeiros!H20 -> #REF! | ... AI17: =Enfermeiros!AI20 -> #REF!
A18: =Enfermeiros!A21 -> #REF! | B18: =Enfermeiros!B21 -> #REF! | C18: =Enfermeiros!C21 -> #REF! | D18: =Enfermeiros!D21 -> #REF! | E18: =Enfermeiros!E21 -> #REF! | F18: =Enfermeiros!F21 -> #REF! | G18: =Enfermeiros!G21 -> #REF! | H18: =Enfermeiros!H21 -> #REF! | ... AI18: =Enfermeiros!AI21 -> #REF!
A19: CENTRO CIRURGICO
A20: =Enfermeiros!A26 -> #REF! | B20: =Enfermeiros!B26 -> #REF! | C20: =Enfermeiros!C26 -> #REF! | D20: =Enfermeiros!D26 -> #REF! | E20: =Enfermeiros!E26 -> #REF! | F20: =Enfermeiros!F26 -> #REF! | G20: =Enfermeiros!G26 -> #REF! | H20: =Enfermeiros!H26 -> #REF! | ... AI20: =Enfermeiros!AI26 -> #REF!
A21: =Enfermeiros!A27 -> #REF! | B21: =Enfermeiros!B27 -> #REF! | C21: =Enfermeiros!C27 -> #REF! | D21: =Enfermeiros!D27 -> #REF! | E21: =Enfermeiros!E27 -> #REF! | F21: =Enfermeiros!F27 -> #REF! | G21: =Enfermeiros!G27 -> #REF! | H21: =Enfermeiros!H27 -> #REF! | ... AI21: =Enfermeiros!AI27 -> #REF!
A22: UTI
A23: =Enfermeiros!A30 -> #REF! | B23: =Enfermeiros!B30 -> #REF! | C23: =Enfermeiros!C30 -> #REF! | D23: =Enfermeiros!D30 -> #REF! | E23: =Enfermeiros!E30 -> #REF! | F23: =Enfermeiros!F30 -> #REF! | G23: =Enfermeiros!G30 -> #REF! | H23: =Enfermeiros!H30 -> #REF! | ... AI23: =Enfermeiros!AI30 -> #REF!
A24: =Enfermeiros!A31 -> #REF! | B24: =Enfermeiros!B31 -> #REF! | C24: =Enfermeiros!C31 -> #REF! | D24: =Enfermeiros!D31 -> #REF! | E24: =Enfermeiros!E31 -> #REF! | F24: =Enfermeiros!F31 -> #REF! | G24: =Enfermeiros!G31 -> #REF! | H24: =Enfermeiros!H31 -> #REF! | ... AI24: =Enfermeiros!AI31 -> #REF!
A25: =Enfermeiros!A32 -> #REF! | B25: =Enfermeiros!B32 -> #REF! | C25: =Enfermeiros!C32 -> #REF! | D25: =Enfermeiros!D32 -> #REF! | E25: =Enfermeiros!E32 -> #REF! | F25: =Enfermeiros!F32 -> #REF! | G25: =Enfermeiros!G32 -> #REF! | H25: =Enfermeiros!H32 -> #REF! | ... AI25: =Enfermeiros!AI32 -> #REF!
A26: PRONTO ATENDIMENTO - NOTURNO
A27: =Enfermeiros!A12 -> #REF! | B27: =Enfermeiros!B12 -> #REF! | C27: =Enfermeiros!C12 -> #REF! | D27: =Enfermeiros!D12 -> #REF! | E27: =Enfermeiros!E12 -> #REF! | F27: =Enfermeiros!F12 -> #REF! | G27: =Enfermeiros!G12 -> #REF! | H27: =Enfermeiros!H12 -> #REF! | ... AI27: =Enfermeiros!AI12 -> #REF!
A28: =Enfermeiros!A13 -> #REF! | B28: =Enfermeiros!B13 -> #REF! | C28: =Enfermeiros!C13 -> #REF! | D28: =Enfermeiros!D13 -> #REF! | E28: =Enfermeiros!E13 -> #REF! | F28: =Enfermeiros!F13 -> #REF! | G28: =Enfermeiros!G13 -> #REF! | H28: =Enfermeiros!H13 -> #REF! | ... AI28: =Enfermeiros!AI13 -> #REF!
A29: ENFERMARIA - NOTURNO
A30: =Enfermeiros!A22 -> #REF! | B30: =Enfermeiros!B22 -> #REF! | C30: =Enfermeiros!C22 -> #REF! | D30: =Enfermeiros!D22 -> #REF! | E30: =Enfermeiros!E22 -> #REF! | P30: =Enfermeiros!P22 -> #REF! | Q30: =Enfermeiros!Q22 -> #REF! | R30: =Enfermeiros!R22 -> #REF! | S30: =Enfermeiros!S22 -> #REF! | T30: =Enfermeiros!T22 -> #REF! | U30: =Enfermeiros!U22 -> #REF! | V30: =Enfermeiros!V22 -> #REF! | W30: =Enfermeiros!W22 -> #REF! | ... AI30: =Enfermeiros!AI22 -> #REF!
A31: =Enfermeiros!A23 -> #REF! | B31: =Enfermeiros!B23 -> #REF! | C31: =Enfermeiros!C23 -> #REF! | D31: =Enfermeiros!D23 -> #REF! | E31: =Enfermeiros!E23 -> #REF! | F31: =Enfermeiros!F23 -> #REF! | G31: =Enfermeiros!G23 -> #REF! | H31: =Enfermeiros!H23 -> #REF! | ... M31: =Enfermeiros!M23 -> #REF!
A32: UTI - NOTURNO
A33: =Enfermeiros!A33 -> #REF! | B33: =Enfermeiros!B33 -> #REF! | C33: =Enfermeiros!C33 -> #REF! | D33: =Enfermeiros!D33 -> #REF! | E33: =Enfermeiros!E33 -> #REF! | F33: =Enfermeiros!F33 -> #REF! | G33: =Enfermeiros!G33 -> #REF! | H33: =Enfermeiros!H33 -> #REF! | ... AI33: =Enfermeiros!AI33 -> #REF!
A34: =Enfermeiros!A34 -> #REF! | B34: =Enfermeiros!B34 -> #REF! | C34: =Enfermeiros!C34 -> #REF! | D34: =Enfermeiros!D34 -> #REF! | E34: =Enfermeiros!E34 -> #REF! | F34: =Enfermeiros!F34 -> #REF! | G34: =Enfermeiros!G34 -> #REF! | H34: =Enfermeiros!H34 -> #REF! | ... AI34: =Enfermeiros!AI34 -> SN
